reported_result/report-2/ART_TFC/output/output4.txt

Iceberg	1	3	6	6	8	SELL	0	---	0
NewOrderRs	Accepted
	Trades	0
	Orders	1
	Order	Iceberg	1	3	6	6	8	SELL	0	---	1
	Credits	7
	Credit	1	14
	Credit	2	10
	Credit	3	11
	Credit	4	11
	Credit	5	7
	Credit	6	3
	Credit	7	13
	Ownerships	7
	Ownership	1	66
	Ownership	2	68
	Ownership	3	35
	Ownership	4	32
	Ownership	5	58
	Ownership	6	22
	Ownership	7	30
	ReferencePrice	5
	StaticPriceBandLowerLimit	0.6
	StaticPriceBandUpperLimit	0.8
	TotalShares	100
	OwnershipUpperLimit	0.2
	TickSize	1
	LotSize	1
Limit	2	6	4	2	8	SELL	0	---	0
NewOrderRs	Accepted
	Trades	0
	Orders	2
	Order	Limit	2	6	4	2	8	SELL	0	---	0
	Order	Iceberg	1	3	6	6	8	SELL	0	---	1
	Credits	7
	Credit	1	14
	Credit	2	10
	Credit	3	11
	Credit	4	11
	Credit	5	7
	Credit	6	3
	Credit	7	13
	Ownerships	7
	Ownership	1	66
	Ownership	2	68
	Ownership	3	35
	Ownership	4	32
	Ownership	5	58
	Ownership	6	22
	Ownership	7	30
	ReferencePrice	5
	StaticPriceBandLowerLimit	0.6
	StaticPriceBandUpperLimit	0.8
	TotalShares	100
	OwnershipUpperLimit	0.2
	TickSize	1
	LotSize	1
Limit	3	6	5	4	7	BUY 	0	---	0
NewOrderRs	Rejected
	Trades	0
	Orders	2
	Order	Limit	2	6	4	2	8	SELL	0	---	0
	Order	Iceberg	1	3	6	6	8	SELL	0	---	1
	Credits	7
	Credit	1	14
	Credit	2	10
	Credit	3	11
	Credit	4	11
	Credit	5	7
	Credit	6	3
	Credit	7	13
	Ownerships	7
	Ownership	1	66
	Ownership	2	68
	Ownership	3	35
	Ownership	4	32
	Ownership	5	58
	Ownership	6	22
	Ownership	7	30
	ReferencePrice	5
	StaticPriceBandLowerLimit	0.6
	StaticPriceBandUpperLimit	0.8
	TotalShares	100
	OwnershipUpperLimit	0.2
	TickSize	1
	LotSize	1
Limit	4	5	1	5	4	SELL	1	---	0
NewOrderRs	Eliminated
	Trades	0
	Orders	2
	Order	Limit	2	6	4	2	8	SELL	0	---	0
	Order	Iceberg	1	3	6	6	8	SELL	0	---	1
	Credits	7
	Credit	1	14
	Credit	2	10
	Credit	3	11
	Credit	4	11
	Credit	5	7
	Credit	6	3
	Credit	7	13
	Ownerships	7
	Ownership	1	66
	Ownership	2	68
	Ownership	3	35
	Ownership	4	32
	Ownership	5	58
	Ownership	6	22
	Ownership	7	30
	ReferencePrice	5
	StaticPriceBandLowerLimit	0.6
	StaticPriceBandUpperLimit	0.8
	TotalShares	100
	OwnershipUpperLimit	0.2
	TickSize	1
	LotSize	1
CancelOrderRs	Rejected
	Orders	2
	Order	Limit	2	6	4	2	8	SELL	0	---	0
	Order	Iceberg	1	3	6	6	8	SELL	0	---	1
	Credits	7
	Credit	1	14
	Credit	2	10
	Credit	3	11
	Credit	4	11
	Credit	5	7
	Credit	6	3
	Credit	7	13
	Ownerships	7
	Ownership	1	66
	Ownership	2	68
	Ownership	3	35
	Ownership	4	32
	Ownership	5	58
	Ownership	6	22
	Ownership	7	30
	ReferencePrice	5
	StaticPriceBandLowerLimit	0.6
	StaticPriceBandUpperLimit	0.8
	TotalShares	100
	OwnershipUpperLimit	0.2
	TickSize	1
	LotSize	1
Limit	6	5	4	5	7	SELL	0	---	0
NewOrderRs	Accepted
	Trades	0
	Orders	3
	Order	Limit	2	6	4	2	8	SELL	0	---	0
	Order	Limit	6	5	4	5	7	SELL	0	---	0
	Order	Iceberg	1	3	6	6	8	SELL	0	---	1
	Credits	7
	Credit	1	14
	Credit	2	10
	Credit	3	11
	Credit	4	11
	Credit	5	7
	Credit	6	3
	Credit	7	13
	Ownerships	7
	Ownership	1	66
	Ownership	2	68
	Ownership	3	35
	Ownership	4	32
	Ownership	5	58
	Ownership	6	22
	Ownership	7	30
	ReferencePrice	5
	StaticPriceBandLowerLimit	0.6
	StaticPriceBandUpperLimit	0.8
	TotalShares	100
	OwnershipUpperLimit	0.2
	TickSize	1
	LotSize	1
Iceberg	7	3	7	7	5	BUY 	0	---	0
NewOrderRs	Rejected
	Trades	0
	Orders	3
	Order	Limit	2	6	4	2	8	SELL	0	---	0
	Order	Limit	6	5	4	5	7	SELL	0	---	0
	Order	Iceberg	1	3	6	6	8	SELL	0	---	1
	Credits	7
	Credit	1	14
	Credit	2	10
	Credit	3	11
	Credit	4	11
	Credit	5	7
	Credit	6	3
	Credit	7	13
	Ownerships	7
	Ownership	1	66
	Ownership	2	68
	Ownership	3	35
	Ownership	4	32
	Ownership	5	58
	Ownership	6	22
	Ownership	7	30
	ReferencePrice	5
	StaticPriceBandLowerLimit	0.6
	StaticPriceBandUpperLimit	0.8
	TotalShares	100
	OwnershipUpperLimit	0.2
	TickSize	1
	LotSize	1
Limit	8	7	2	7	5	BUY 	0	FAK	0
NewOrderRs	Rejected
	Trades	0
	Orders	3
	Order	Limit	2	6	4	2	8	SELL	0	---	0
	Order	Limit	6	5	4	5	7	SELL	0	---	0
	Order	Iceberg	1	3	6	6	8	SELL	0	---	1
	Credits	7
	Credit	1	14
	Credit	2	10
	Credit	3	11
	Credit	4	11
	Credit	5	7
	Credit	6	3
	Credit	7	13
	Ownerships	7
	Ownership	1	66
	Ownership	2	68
	Ownership	3	35
	Ownership	4	32
	Ownership	5	58
	Ownership	6	22
	Ownership	7	30
	ReferencePrice	5
	StaticPriceBandLowerLimit	0.6
	StaticPriceBandUpperLimit	0.8
	TotalShares	100
	OwnershipUpperLimit	0.2
	TickSize	1
	LotSize	1
Limit	9	1	1	6	5	SELL	0	FAK	0
NewOrderRs	Eliminated
	Trades	0
	Orders	3
	Order	Limit	2	6	4	2	8	SELL	0	---	0
	Order	Limit	6	5	4	5	7	SELL	0	---	0
	Order	Iceberg	1	3	6	6	8	SELL	0	---	1
	Credits	7
	Credit	1	14
	Credit	2	10
	Credit	3	11
	Credit	4	11
	Credit	5	7
	Credit	6	3
	Credit	7	13
	Ownerships	7
	Ownership	1	66
	Ownership	2	68
	Ownership	3	35
	Ownership	4	32
	Ownership	5	58
	Ownership	6	22
	Ownership	7	30
	ReferencePrice	5
	StaticPriceBandLowerLimit	0.6
	StaticPriceBandUpperLimit	0.8
	TotalShares	100
	OwnershipUpperLimit	0.2
	TickSize	1
	LotSize	1
Limit	10	1	1	8	7	SELL	2	---	0
ReplaceOrderRs	Rejected
	Trades	0
	Orders	3
	Order	Limit	2	6	4	2	8	SELL	0	---	0
	Order	Limit	6	5	4	5	7	SELL	0	---	0
	Order	Iceberg	1	3	6	6	8	SELL	0	---	1
	Credits	7
	Credit	1	14
	Credit	2	10
	Credit	3	11
	Credit	4	11
	Credit	5	7
	Credit	6	3
	Credit	7	13
	Ownerships	7
	Ownership	1	66
	Ownership	2	68
	Ownership	3	35
	Ownership	4	32
	Ownership	5	58
	Ownership	6	22
	Ownership	7	30
	ReferencePrice	5
	StaticPriceBandLowerLimit	0.6
	StaticPriceBandUpperLimit	0.8
	TotalShares	100
	OwnershipUpperLimit	0.2
	TickSize	1
	LotSize	1
Iceberg	11	2	1	7	1	SELL	0	---	0
NewOrderRs	Accepted
	Trades	0
	Orders	4
	Order	Limit	2	6	4	2	8	SELL	0	---	0
	Order	Limit	6	5	4	5	7	SELL	0	---	0
	Order	Iceberg	1	3	6	6	8	SELL	0	---	1
	Order	Iceberg	11	2	1	7	1	SELL	0	---	1
	Credits	7
	Credit	1	14
	Credit	2	10
	Credit	3	11
	Credit	4	11
	Credit	5	7
	Credit	6	3
	Credit	7	13
	Ownerships	7
	Ownership	1	66
	Ownership	2	68
	Ownership	3	35
	Ownership	4	32
	Ownership	5	58
	Ownership	6	22
	Ownership	7	30
	ReferencePrice	5
	StaticPriceBandLowerLimit	0.6
	StaticPriceBandUpperLimit	0.8
	TotalShares	100
	OwnershipUpperLimit	0.2
	TickSize	1
	LotSize	1
Limit	12	4	7	7	4	SELL	0	---	0
NewOrderRs	Accepted
	Trades	0
	Orders	5
	Order	Limit	2	6	4	2	8	SELL	0	---	0
	Order	Limit	6	5	4	5	7	SELL	0	---	0
	Order	Iceberg	1	3	6	6	8	SELL	0	---	1
	Order	Iceberg	11	2	1	7	1	SELL	0	---	1
	Order	Limit	12	4	7	7	4	SELL	0	---	0
	Credits	7
	Credit	1	14
	Credit	2	10
	Credit	3	11
	Credit	4	11
	Credit	5	7
	Credit	6	3
	Credit	7	13
	Ownerships	7
	Ownership	1	66
	Ownership	2	68
	Ownership	3	35
	Ownership	4	32
	Ownership	5	58
	Ownership	6	22
	Ownership	7	30
	ReferencePrice	5
	StaticPriceBandLowerLimit	0.6
	StaticPriceBandUpperLimit	0.8
	TotalShares	100
	OwnershipUpperLimit	0.2
	TickSize	1
	LotSize	1
Iceberg	13	6	5	9	4	BUY 	0	---	0
NewOrderRs	Rejected
	Trades	0
	Orders	5
	Order	Limit	2	6	4	2	8	SELL	0	---	0
	Order	Limit	6	5	4	5	7	SELL	0	---	0
	Order	Iceberg	1	3	6	6	8	SELL	0	---	1
	Order	Iceberg	11	2	1	7	1	SELL	0	---	1
	Order	Limit	12	4	7	7	4	SELL	0	---	0
	Credits	7
	Credit	1	14
	Credit	2	10
	Credit	3	11
	Credit	4	11
	Credit	5	7
	Credit	6	3
	Credit	7	13
	Ownerships	7
	Ownership	1	66
	Ownership	2	68
	Ownership	3	35
	Ownership	4	32
	Ownership	5	58
	Ownership	6	22
	Ownership	7	30
	ReferencePrice	5
	StaticPriceBandLowerLimit	0.6
	StaticPriceBandUpperLimit	0.8
	TotalShares	100
	OwnershipUpperLimit	0.2
	TickSize	1
	LotSize	1
Limit	14	2	6	5	8	SELL	0	---	0
NewOrderRs	Accepted
	Trades	0
	Orders	6
	Order	Limit	2	6	4	2	8	SELL	0	---	0
	Order	Limit	6	5	4	5	7	SELL	0	---	0
	Order	Limit	14	2	6	5	8	SELL	0	---	0
	Order	Iceberg	1	3	6	6	8	SELL	0	---	1
	Order	Iceberg	11	2	1	7	1	SELL	0	---	1
	Order	Limit	12	4	7	7	4	SELL	0	---	0
	Credits	7
	Credit	1	14
	Credit	2	10
	Credit	3	11
	Credit	4	11
	Credit	5	7
	Credit	6	3
	Credit	7	13
	Ownerships	7
	Ownership	1	66
	Ownership	2	68
	Ownership	3	35
	Ownership	4	32
	Ownership	5	58
	Ownership	6	22
	Ownership	7	30
	ReferencePrice	5
	StaticPriceBandLowerLimit	0.6
	StaticPriceBandUpperLimit	0.8
	TotalShares	100
	OwnershipUpperLimit	0.2
	TickSize	1
	LotSize	1
CancelOrderRs	Accepted
	Orders	5
	Order	Limit	2	6	4	2	8	SELL	0	---	0
	Order	Limit	6	5	4	5	7	SELL	0	---	0
	Order	Iceberg	1	3	6	6	8	SELL	0	---	1
	Order	Iceberg	11	2	1	7	1	SELL	0	---	1
	Order	Limit	12	4	7	7	4	SELL	0	---	0
	Credits	7
