reported_result/report-2/ART_TFC/output/output6.txt

Iceberg	1	3	1	10	2	SELL	1	---	0
NewOrderRs	Rejected
	Trades	0
	Orders	0
	Credits	7
	Credit	1	17
	Credit	2	15
	Credit	3	10
	Credit	4	13
	Credit	5	7
	Credit	6	9
	Credit	7	16
	Ownerships	7
	Ownership	1	52
	Ownership	2	66
	Ownership	3	53
	Ownership	4	41
	Ownership	5	29
	Ownership	6	81
	Ownership	7	75
	ReferencePrice	5
	StaticPriceBandLowerLimit	0.6
	StaticPriceBandUpperLimit	0.8
	TotalShares	100
	OwnershipUpperLimit	0.2
	TickSize	1
	LotSize	1
Limit	2	7	1	3	2	BUY 	0	---	0
NewOrderRs	Rejected
	Trades	0
	Orders	0
	Credits	7
	Credit	1	17
	Credit	2	15
	Credit	3	10
	Credit	4	13
	Credit	5	7
	Credit	6	9
	Credit	7	16
	Ownerships	7
	Ownership	1	52
	Ownership	2	66
	Ownership	3	53
	Ownership	4	41
	Ownership	5	29
	Ownership	6	81
	Ownership	7	75
	ReferencePrice	5
	StaticPriceBandLowerLimit	0.6
	StaticPriceBandUpperLimit	0.8
	TotalShares	100
	OwnershipUpperLimit	0.2
	TickSize	1
	LotSize	1
Iceberg	3	4	2	5	8	SELL	0	---	0
NewOrderRs	Accepted
	Trades	0
	Orders	1
	Order	Iceberg	3	4	2	5	8	SELL	0	---	2
	Credits	7
	Credit	1	17
	Credit	2	15
	Credit	3	10
	Credit	4	13
	Credit	5	7
	Credit	6	9
	Credit	7	16
	Ownerships	7
	Ownership	1	52
	Ownership	2	66
	Ownership	3	53
	Ownership	4	41
	Ownership	5	29
	Ownership	6	81
	Ownership	7	75
	ReferencePrice	5
	StaticPriceBandLowerLimit	0.6
	StaticPriceBandUpperLimit	0.8
	TotalShares	100
	OwnershipUpperLimit	0.2
	TickSize	1
	LotSize	1
Iceberg	4	2	3	3	8	BUY 	0	---	0
NewOrderRs	Rejected
	Trades	0
	Orders	1
	Order	Iceberg	3	4	2	5	8	SELL	0	---	2
	Credits	7
	Credit	1	17
	Credit	2	15
	Credit	3	10
	Credit	4	13
	Credit	5	7
	Credit	6	9
	Credit	7	16
	Ownerships	7
	Ownership	1	52
	Ownership	2	66
	Ownership	3	53
	Ownership	4	41
	Ownership	5	29
	Ownership	6	81
	Ownership	7	75
	ReferencePrice	5
	StaticPriceBandLowerLimit	0.6
	StaticPriceBandUpperLimit	0.8
	TotalShares	100
	OwnershipUpperLimit	0.2
	TickSize	1
	LotSize	1
CancelOrderRs	Rejected
	Orders	1
	Order	Iceberg	3	4	2	5	8	SELL	0	---	2
	Credits	7
	Credit	1	17
	Credit	2	15
	Credit	3	10
	Credit	4	13
	Credit	5	7
	Credit	6	9
	Credit	7	16
	Ownerships	7
	Ownership	1	52
	Ownership	2	66
	Ownership	3	53
	Ownership	4	41
	Ownership	5	29
	Ownership	6	81
	Ownership	7	75
	ReferencePrice	5
	StaticPriceBandLowerLimit	0.6
	StaticPriceBandUpperLimit	0.8
	TotalShares	100
	OwnershipUpperLimit	0.2
	TickSize	1
	LotSize	1
Iceberg	6	1	7	6	5	SELL	0	---	0
NewOrderRs	Accepted
	Trades	0
	Orders	2
	Order	Iceberg	3	4	2	5	8	SELL	0	---	2
	Order	Iceberg	6	1	7	6	5	SELL	0	---	4
	Credits	7
	Credit	1	17
	Credit	2	15
	Credit	3	10
	Credit	4	13
	Credit	5	7
	Credit	6	9
	Credit	7	16
	Ownerships	7
	Ownership	1	52
	Ownership	2	66
	Ownership	3	53
	Ownership	4	41
	Ownership	5	29
	Ownership	6	81
	Ownership	7	75
	ReferencePrice	5
	StaticPriceBandLowerLimit	0.6
	StaticPriceBandUpperLimit	0.8
	TotalShares	100
	OwnershipUpperLimit	0.2
	TickSize	1
	LotSize	1
Limit	7	6	6	9	3	SELL	3	---	0
NewOrderRs	Eliminated
	Trades	0
	Orders	2
	Order	Iceberg	3	4	2	5	8	SELL	0	---	2
	Order	Iceberg	6	1	7	6	5	SELL	0	---	4
	Credits	7
	Credit	1	17
	Credit	2	15
	Credit	3	10
	Credit	4	13
	Credit	5	7
	Credit	6	9
	Credit	7	16
	Ownerships	7
	Ownership	1	52
	Ownership	2	66
	Ownership	3	53
	Ownership	4	41
	Ownership	5	29
	Ownership	6	81
	Ownership	7	75
	ReferencePrice	5
	StaticPriceBandLowerLimit	0.6
	StaticPriceBandUpperLimit	0.8
	TotalShares	100
	OwnershipUpperLimit	0.2
	TickSize	1
	LotSize	1
Limit	8	4	4	9	5	SELL	0	FAK	0
NewOrderRs	Eliminated
	Trades	0
	Orders	2
	Order	Iceberg	3	4	2	5	8	SELL	0	---	2
	Order	Iceberg	6	1	7	6	5	SELL	0	---	4
	Credits	7
	Credit	1	17
	Credit	2	15
	Credit	3	10
	Credit	4	13
	Credit	5	7
	Credit	6	9
	Credit	7	16
	Ownerships	7
	Ownership	1	52
	Ownership	2	66
	Ownership	3	53
	Ownership	4	41
	Ownership	5	29
	Ownership	6	81
	Ownership	7	75
	ReferencePrice	5
	StaticPriceBandLowerLimit	0.6
	StaticPriceBandUpperLimit	0.8
	TotalShares	100
	OwnershipUpperLimit	0.2
	TickSize	1
	LotSize	1
Iceberg	9	3	6	5	5	SELL	1	---	0
NewOrderRs	Eliminated
	Trades	0
	Orders	2
	Order	Iceberg	3	4	2	5	8	SELL	0	---	2
	Order	Iceberg	6	1	7	6	5	SELL	0	---	4
	Credits	7
	Credit	1	17
	Credit	2	15
	Credit	3	10
	Credit	4	13
	Credit	5	7
	Credit	6	9
	Credit	7	16
	Ownerships	7
	Ownership	1	52
	Ownership	2	66
	Ownership	3	53
	Ownership	4	41
	Ownership	5	29
	Ownership	6	81
	Ownership	7	75
	ReferencePrice	5
	StaticPriceBandLowerLimit	0.6
	StaticPriceBandUpperLimit	0.8
	TotalShares	100
	OwnershipUpperLimit	0.2
	TickSize	1
	LotSize	1
Iceberg	10	3	6	6	1	SELL	1	---	0
ReplaceOrderRs	Rejected
	Trades	0
	Orders	2
	Order	Iceberg	3	4	2	5	8	SELL	0	---	2
	Order	Iceberg	6	1	7	6	5	SELL	0	---	4
	Credits	7
	Credit	1	17
	Credit	2	15
	Credit	3	10
	Credit	4	13
	Credit	5	7
	Credit	6	9
	Credit	7	16
	Ownerships	7
	Ownership	1	52
	Ownership	2	66
	Ownership	3	53
	Ownership	4	41
	Ownership	5	29
	Ownership	6	81
	Ownership	7	75
	ReferencePrice	5
	StaticPriceBandLowerLimit	0.6
	StaticPriceBandUpperLimit	0.8
	TotalShares	100
	OwnershipUpperLimit	0.2
	TickSize	1
	LotSize	1
Limit	11	1	2	2	6	SELL	0	FAK	0
NewOrderRs	Eliminated
	Trades	0
	Orders	2
	Order	Iceberg	3	4	2	5	8	SELL	0	---	2
	Order	Iceberg	6	1	7	6	5	SELL	0	---	4
	Credits	7
	Credit	1	17
	Credit	2	15
	Credit	3	10
	Credit	4	13
	Credit	5	7
	Credit	6	9
	Credit	7	16
	Ownerships	7
	Ownership	1	52
	Ownership	2	66
	Ownership	3	53
	Ownership	4	41
	Ownership	5	29
	Ownership	6	81
	Ownership	7	75
	ReferencePrice	5
	StaticPriceBandLowerLimit	0.6
	StaticPriceBandUpperLimit	0.8
	TotalShares	100
	OwnershipUpperLimit	0.2
	TickSize	1
	LotSize	1
Limit	12	4	5	2	2	BUY 	1	---	0
NewOrderRs	Rejected
	Trades	0
	Orders	2
	Order	Iceberg	3	4	2	5	8	SELL	0	---	2
	Order	Iceberg	6	1	7	6	5	SELL	0	---	4
	Credits	7
	Credit	1	17
	Credit	2	15
	Credit	3	10
	Credit	4	13
	Credit	5	7
	Credit	6	9
	Credit	7	16
	Ownerships	7
	Ownership	1	52
	Ownership	2	66
	Ownership	3	53
	Ownership	4	41
	Ownership	5	29
	Ownership	6	81
	Ownership	7	75
	ReferencePrice	5
	StaticPriceBandLowerLimit	0.6
	StaticPriceBandUpperLimit	0.8
	TotalShares	100
	OwnershipUpperLimit	0.2
	TickSize	1
	LotSize	1
Limit	13	1	1	3	2	BUY 	0	FAK	0
NewOrderRs	Rejected
	Trades	0
	Orders	2
	Order	Iceberg	3	4	2	5	8	SELL	0	---	2
	Order	Iceberg	6	1	7	6	5	SELL	0	---	4
	Credits	7
	Credit	1	17
	Credit	2	15
	Credit	3	10
	Credit	4	13
	Credit	5	7
	Credit	6	9
	Credit	7	16
	Ownerships	7
	Ownership	1	52
	Ownership	2	66
	Ownership	3	53
	Ownership	4	41
	Ownership	5	29
	Ownership	6	81
	Ownership	7	75
	ReferencePrice	5
	StaticPriceBandLowerLimit	0.6
	StaticPriceBandUpperLimit	0.8
	TotalShares	100
	OwnershipUpperLimit	0.2
	TickSize	1
	LotSize	1
Iceberg	14	1	3	9	7	BUY 	2	---	0
NewOrderRs	Rejected
	Trades	0
	Orders	2
	Order	Iceberg	3	4	2	5	8	SELL	0	---	2
	Order	Iceberg	6	1	7	6	5	SELL	0	---	4
	Credits	7
	Credit	1	17
	Credit	2	15
	Credit	3	10
	Credit	4	13
	Credit	5	7
	Credit	6	9
	Credit	7	16
	Ownerships	7
	Ownership	1	52
	Ownership	2	66
	Ownership	3	53
	Ownership	4	41
	Ownership	5	29
	Ownership	6	81
	Ownership	7	75
	ReferencePrice	5
	StaticPriceBandLowerLimit	0.6
	StaticPriceBandUpperLimit	0.8
	TotalShares	100
	OwnershipUpperLimit	0.2
	TickSize	1
	LotSize	1
CancelOrderRs	Rejected
	Orders	2
	Order	Iceberg	3	4	2	5	8	SELL	0	---	2
	Order	Iceberg	6	1	7	6	5	SELL	0	---	4
	Credits	7
	Credit	1	17
	Credit	2	15
	Credit	3	10
	Credit	4	13
	Credit	5	7
	Credit	6	9
	Credit	7	16
	Ownerships	7
	Ownership	1	52
	Ownership	2	66
	Ownership	3	53
	Ownership	4	41
	Ownership	5	29
	Ownership	6	81
	Ownership	7	75
	ReferencePrice	5
	StaticPriceBandLowerLimit	0.6
	StaticPriceBandUpperLimit	0.8
	TotalShares	100
	OwnershipUpperLimit	0.2
	TickSize	1
	LotSize	1
Limit	16	6	1	7	2	SELL	0	---	0
NewOrderRs	Accepted
	Trades	0
	Orders	3
	Order	Iceberg	3	4	2	5	8	SELL	0	---	2
	Order	Iceberg	6	1	7	6	5	SELL	0	---	4
	Order	Limit	16	6	1	7	2	SELL	0	---	0
	Credits	7
	Credit	1	17
	Credit	2	15
	Credit	3	10
	Credit	4	13
	Credit	5	7
	Credit	6	9
	Credit	7	16
	Ownerships	7
	Ownership	1	52
	Ownership	2	66
	Ownership	3	53
	Ownership	4	41
	Ownership	5	29
	Ownership	6	81
	Ownership	7	75
	ReferencePrice	5
	StaticPriceBandLowerLimit	0.6
	StaticPriceBandUpperLimit	0.8
	TotalShares	100
	OwnershipUpperLimit	0.2
	TickSize	1
	LotSize	1
Iceberg	17	6	5	2	6	BUY 	0	---	0
